Traceback (most recent call last):
  File "/Users/larahabashy/Downloads/miniconda3/lib/python3.8/site-packages/jupyter_cache/executors/utils.py", line 51, in single_nb_execution
    executenb(
  File "/Users/larahabashy/Downloads/miniconda3/lib/python3.8/site-packages/nbclient/client.py", line 1107, in execute
    return NotebookClient(nb=nb, resources=resources, km=km, **kwargs).execute()
  File "/Users/larahabashy/Downloads/miniconda3/lib/python3.8/site-packages/nbclient/util.py", line 74, in wrapped
    return just_run(coro(*args, **kwargs))
  File "/Users/larahabashy/Downloads/miniconda3/lib/python3.8/site-packages/nbclient/util.py", line 53, in just_run
    return loop.run_until_complete(coro)
  File "/Users/larahabashy/Downloads/miniconda3/lib/python3.8/asyncio/base_events.py", line 616, in run_until_complete
    return future.result()
  File "/Users/larahabashy/Downloads/miniconda3/lib/python3.8/site-packages/nbclient/client.py", line 553, in async_execute
    await self.async_execute_cell(
  File "/Users/larahabashy/Downloads/miniconda3/lib/python3.8/site-packages/nbclient/client.py", line 852, in async_execute_cell
    self._check_raise_for_error(cell, exec_reply)
  File "/Users/larahabashy/Downloads/miniconda3/lib/python3.8/site-packages/nbclient/client.py", line 760, in _check_raise_for_error
    raise CellExecutionError.from_cell_and_msg(cell, exec_reply_content)
nbclient.exceptions.CellExecutionError: An error occurred while executing the following cell:
------------------
fig = figure(figsize=(10, 8))
a=fig.add_subplot(1,1,1)
image = imread("proposal_feature_importance.PNG")
imshow(image)
axis('off')
txt = "Figure 2: Feature Importance. The lighter orange and yellow areas on the right represent areas that \n the baseline model thinks are important for detecting lipohypertrophy."
_ = figtext(0.5, 0.10, txt, horizontalalignment='center', fontsize=14)
------------------

[0;31m---------------------------------------------------------------------------[0m
[0;31mNameError[0m                                 Traceback (most recent call last)
[0;32m<ipython-input-1-1352b7c280cf>[0m in [0;36m<module>[0;34m[0m
[0;32m----> 1[0;31m [0mfig[0m [0;34m=[0m [0mfigure[0m[0;34m([0m[0mfigsize[0m[0;34m=[0m[0;34m([0m[0;36m10[0m[0;34m,[0m [0;36m8[0m[0;34m)[0m[0;34m)[0m[0;34m[0m[0;34m[0m[0m
[0m[1;32m      2[0m [0ma[0m[0;34m=[0m[0mfig[0m[0;34m.[0m[0madd_subplot[0m[0;34m([0m[0;36m1[0m[0;34m,[0m[0;36m1[0m[0;34m,[0m[0;36m1[0m[0;34m)[0m[0;34m[0m[0;34m[0m[0m
[1;32m      3[0m [0mimage[0m [0;34m=[0m [0mimread[0m[0;34m([0m[0;34m"proposal_feature_importance.PNG"[0m[0;34m)[0m[0;34m[0m[0;34m[0m[0m
[1;32m      4[0m [0mimshow[0m[0;34m([0m[0mimage[0m[0;34m)[0m[0;34m[0m[0;34m[0m[0m
[1;32m      5[0m [0maxis[0m[0;34m([0m[0;34m'off'[0m[0;34m)[0m[0;34m[0m[0;34m[0m[0m

[0;31mNameError[0m: name 'figure' is not defined
NameError: name 'figure' is not defined

